2021-08-31T02:43:48.324894+0100 - update - INFO - ['note', 'idem\nidem\n', '506']
2021-08-31T02:43:48.329135+0100 - update - INFO - UPDATE notes SET %s = %s WHERE id = %s
2021-08-31T02:45:38.186262+0100 - update - INFO - ['title', 'tlim\n', '506']
2021-08-31T02:45:38.190345+0100 - update - INFO - UPDATE notes SET %s = %s WHERE id = %s
2021-08-31T02:46:15.418576+0100 - search - INFO - mysql
2021-08-31T02:46:15.425839+0100 - search - INFO -  SELECT ntid, title, k1, k2, k3, note, url, time FROM notes WHERE MATCH(title, k1, k2, k3, note, url) AGAINST ('mysql' )
2021-08-31T02:47:51.805780+0100 - update - INFO - ['title', 'tlim\n', '506']
2021-08-31T02:47:51.810496+0100 - update - INFO - UPDATE notes SET %s = %s WHERE id = %s
2021-08-31T04:11:53.842276+0100 - __main__ - INFO - 520
2021-08-31T04:11:53.850138+0100 - __main__ - INFO -  DELETE FROM notes WHERE ntid = 520
2021-08-31T04:11:53.855389+0100 - __main__ - INFO - SELECT url FROM notes WHERE ntid = 520
2021-08-31T04:11:53.856091+0100 - __main__ - ERROR - An error has been caught in function '<module>', process 'MainProcess' (478562), thread 'MainThread' (139773375313728):
Traceback (most recent call last):

> File "/home/mic/python/notes/delete.py", line 63, in <module>
    delete_md_html_pages()
    └ <function delete_md_html_pages at 0x7f1f85577700>

  File "/home/mic/python/notes/delete.py", line 52, in delete_md_html_pages
    md_page = "/srv/http/notes/pages/markdown/" + filename + "'"

UnboundLocalError: local variable 'filename' referenced before assignment
2021-08-31T04:11:53.856091+0100 - __main__ - ERROR - An error has been caught in function '<module>', process 'MainProcess' (478562), thread 'MainThread' (139773375313728):
Traceback (most recent call last):

> File "/home/mic/python/notes/delete.py", line 63, in <module>
    delete_md_html_pages()
    └ <function delete_md_html_pages at 0x7f1f85577700>

  File "/home/mic/python/notes/delete.py", line 52, in delete_md_html_pages
    md_page = "/srv/http/notes/pages/markdown/" + filename + "'"

UnboundLocalError: local variable 'filename' referenced before assignment
2021-08-31T04:13:44.712232+0100 - __main__ - INFO - 519
2021-08-31T04:13:44.726820+0100 - __main__ - INFO -  DELETE FROM notes WHERE ntid = 519
2021-08-31T04:13:44.738657+0100 - __main__ - INFO - SELECT url FROM notes WHERE ntid = 519
2021-08-31T04:14:44.847419+0100 - __main__ - INFO - 508
2021-08-31T04:14:44.861738+0100 - __main__ - INFO -  DELETE FROM notes WHERE ntid = 508
2021-08-31T04:14:44.877607+0100 - __main__ - INFO - SELECT url FROM notes WHERE ntid = 508
2021-08-31T04:20:28.191508+0100 - __main__ - INFO - 508
2021-08-31T04:20:28.205722+0100 - __main__ - INFO -  DELETE FROM notes WHERE ntid = 508
2021-08-31T04:20:28.215468+0100 - __main__ - INFO - SELECT url FROM notes WHERE ntid = 508
2021-08-31T04:20:28.217030+0100 - __main__ - INFO - []
2021-08-31T04:21:14.904389+0100 - __main__ - INFO - 509
2021-08-31T04:21:14.918161+0100 - __main__ - INFO -  DELETE FROM notes WHERE ntid = 509
2021-08-31T04:21:14.930736+0100 - __main__ - INFO - SELECT url FROM notes WHERE ntid = 509
2021-08-31T04:21:14.932256+0100 - __main__ - INFO - []
2021-08-31T04:23:11.924725+0100 - __main__ - INFO - 510
2021-08-31T04:23:11.932076+0100 - __main__ - INFO -  DELETE FROM notes WHERE ntid = 510
2021-08-31T04:23:11.936397+0100 - __main__ - INFO - SELECT url FROM notes WHERE ntid = 510
2021-08-31T04:23:11.936757+0100 - __main__ - INFO - []
2021-08-31T04:28:00.750686+0100 - __main__ - INFO - 511
2021-08-31T04:28:00.764424+0100 - __main__ - INFO -  DELETE FROM notes WHERE ntid = 511
2021-08-31T04:28:00.776160+0100 - __main__ - INFO - SELECT url FROM notes WHERE ntid = 511
2021-08-31T04:28:00.777521+0100 - __main__ - INFO - None
2021-08-31T04:28:00.778171+0100 - __main__ - ERROR - An error has been caught in function '<module>', process 'MainProcess' (479188), thread 'MainThread' (140612442728256):
Traceback (most recent call last):

> File "/home/mic/python/notes/delete.py", line 66, in <module>
    delete_md_html_pages()
    └ <function delete_md_html_pages at 0x7fe2e1a83700>

  File "/home/mic/python/notes/delete.py", line 51, in delete_md_html_pages
    for row in records:
               └ None

TypeError: 'NoneType' object is not iterable
2021-08-31T04:28:00.778171+0100 - __main__ - ERROR - An error has been caught in function '<module>', process 'MainProcess' (479188), thread 'MainThread' (140612442728256):
Traceback (most recent call last):

> File "/home/mic/python/notes/delete.py", line 66, in <module>
    delete_md_html_pages()
    └ <function delete_md_html_pages at 0x7fe2e1a83700>

  File "/home/mic/python/notes/delete.py", line 51, in delete_md_html_pages
    for row in records:
               └ None

TypeError: 'NoneType' object is not iterable
2021-08-31T04:28:53.906734+0100 - __main__ - INFO - 512
2021-08-31T04:28:53.914137+0100 - __main__ - INFO -  DELETE FROM notes WHERE ntid = 512
2021-08-31T04:28:53.918816+0100 - __main__ - INFO - SELECT url FROM notes WHERE ntid = 512
2021-08-31T04:28:53.919232+0100 - __main__ - INFO - None
2021-08-31T04:28:53.919382+0100 - __main__ - ERROR - An error has been caught in function '<module>', process 'MainProcess' (479245), thread 'MainThread' (139769827788608):
Traceback (most recent call last):

> File "/home/mic/python/notes/delete.py", line 66, in <module>
    delete_md_html_pages()
    └ <function delete_md_html_pages at 0x7f1eb1e48700>

  File "/home/mic/python/notes/delete.py", line 51, in delete_md_html_pages
    for row in records:
               └ None

TypeError: 'NoneType' object is not iterable
2021-08-31T04:28:53.919382+0100 - __main__ - ERROR - An error has been caught in function '<module>', process 'MainProcess' (479245), thread 'MainThread' (139769827788608):
Traceback (most recent call last):

> File "/home/mic/python/notes/delete.py", line 66, in <module>
    delete_md_html_pages()
    └ <function delete_md_html_pages at 0x7f1eb1e48700>

  File "/home/mic/python/notes/delete.py", line 51, in delete_md_html_pages
    for row in records:
               └ None

TypeError: 'NoneType' object is not iterable
2021-08-31T04:34:20.486740+0100 - __main__ - ERROR - An error has been caught in function '<module>', process 'MainProcess' (479416), thread 'MainThread' (140448475404096):
Traceback (most recent call last):

> File "/home/mic/python/notes/delete.py", line 41, in <module>
    delete_md_html_pages()
    └ <function delete_md_html_pages at 0x7fbcb46e0d30>

  File "/home/mic/python/notes/delete.py", line 22, in delete_md_html_pages
    query = "SELECT url FROM notes WHERE ntid = " + delete.ident

NameError: name 'delete' is not defined
2021-08-31T04:34:20.486740+0100 - __main__ - ERROR - An error has been caught in function '<module>', process 'MainProcess' (479416), thread 'MainThread' (140448475404096):
Traceback (most recent call last):

> File "/home/mic/python/notes/delete.py", line 41, in <module>
    delete_md_html_pages()
    └ <function delete_md_html_pages at 0x7fbcb46e0d30>

  File "/home/mic/python/notes/delete.py", line 22, in delete_md_html_pages
    query = "SELECT url FROM notes WHERE ntid = " + delete.ident

NameError: name 'delete' is not defined
2021-08-31T04:34:25.407924+0100 - __main__ - INFO - 513
2021-08-31T04:34:25.415314+0100 - __main__ - INFO -  DELETE FROM notes WHERE ntid = 513
2021-08-31T04:37:45.348787+0100 - __main__ - INFO - 513
2021-08-31T04:37:45.356647+0100 - __main__ - INFO - SELECT url FROM notes WHERE ntid = 513
2021-08-31T04:37:45.357038+0100 - __main__ - INFO - None
2021-08-31T04:37:45.357184+0100 - __main__ - ERROR - An error has been caught in function '<module>', process 'MainProcess' (479520), thread 'MainThread' (140228692244288):
Traceback (most recent call last):

> File "/home/mic/python/notes/delete.py", line 44, in <module>
    delete_md_html_pages()
    └ <function delete_md_html_pages at 0x7f8988551ca0>

  File "/home/mic/python/notes/delete.py", line 30, in delete_md_html_pages
    filename = os.path.basename(record)
               │  │    │        └ None
               │  │    └ <function basename at 0x7f89891d2a60>
               │  └ <module 'posixpath' from '/usr/lib/python3.9/posixpath.py'>
               └ <module 'os' from '/usr/lib/python3.9/os.py'>

  File "/usr/lib/python3.9/posixpath.py", line 142, in basename
    p = os.fspath(p)
        │  │      └ None
        │  └ <built-in function fspath>
        └ <module 'os' from '/usr/lib/python3.9/os.py'>

TypeError: expected str, bytes or os.PathLike object, not NoneType
2021-08-31T04:37:45.357184+0100 - __main__ - ERROR - An error has been caught in function '<module>', process 'MainProcess' (479520), thread 'MainThread' (140228692244288):
Traceback (most recent call last):

> File "/home/mic/python/notes/delete.py", line 44, in <module>
    delete_md_html_pages()
    └ <function delete_md_html_pages at 0x7f8988551ca0>

  File "/home/mic/python/notes/delete.py", line 30, in delete_md_html_pages
    filename = os.path.basename(record)
               │  │    │        └ None
               │  │    └ <function basename at 0x7f89891d2a60>
               │  └ <module 'posixpath' from '/usr/lib/python3.9/posixpath.py'>
               └ <module 'os' from '/usr/lib/python3.9/os.py'>

  File "/usr/lib/python3.9/posixpath.py", line 142, in basename
    p = os.fspath(p)
        │  │      └ None
        │  └ <built-in function fspath>
        └ <module 'os' from '/usr/lib/python3.9/os.py'>

TypeError: expected str, bytes or os.PathLike object, not NoneType
2021-08-31T04:37:45.363670+0100 - __main__ - INFO -  DELETE FROM notes WHERE ntid = 513
