2021-08-30T22:52:45.781004+0100 - __main__ - ERROR - An error has been caught in function '<module>', process 'MainProcess' (464207), thread 'MainThread' (140335139718976):
Traceback (most recent call last):

> File "/home/mic/python/notes/add_md_page.py", line 17, in <module>
    add_md_page()
    └ <function add_md_page at 0x7fa2511a04c0>

  File "/home/mic/python/notes/add_md_page.py", line 13, in add_md_page
    print(add.tit)
          └ <module 'add' from '/home/mic/python/notes/add.py'>

AttributeError: module 'add' has no attribute 'tit'
2021-08-30T22:53:27.299373+0100 - __main__ - ERROR - An error has been caught in function '<module>', process 'MainProcess' (464218), thread 'MainThread' (139934953535296):
Traceback (most recent call last):

> File "/home/mic/python/notes/add_md_page.py", line 17, in <module>
    add_md_page()
    └ <function add_md_page at 0x7f45242564c0>

  File "/home/mic/python/notes/add_md_page.py", line 13, in add_md_page
    print(add.titulo)
          └ <module 'add' from '/home/mic/python/notes/add.py'>

AttributeError: module 'add' has no attribute 'titulo'
2021-08-30T22:53:43.283379+0100 - __main__ - ERROR - An error has been caught in function '<module>', process 'MainProcess' (464244), thread 'MainThread' (139998646310720):
Traceback (most recent call last):

> File "/home/mic/python/notes/add_md_page.py", line 17, in <module>
    add_md_page()
    └ <function add_md_page at 0x7f53f88804c0>

  File "/home/mic/python/notes/add_md_page.py", line 13, in add_md_page
    print(add.titulo())
          └ <module 'add' from '/home/mic/python/notes/add.py'>

AttributeError: module 'add' has no attribute 'titulo'
2021-08-30T22:54:53.645351+0100 - __main__ - ERROR - An error has been caught in function '<module>', process 'MainProcess' (464303), thread 'MainThread' (139892786030400):
Traceback (most recent call last):

> File "/home/mic/python/notes/add_md_page.py", line 17, in <module>
    add_md_page()
    └ <function add_md_page at 0x7f3b52c454c0>

  File "/home/mic/python/notes/add_md_page.py", line 13, in add_md_page
    print(add.titulo())
          └ <module 'add' from '/home/mic/python/notes/add.py'>

AttributeError: module 'add' has no attribute 'titulo'
2021-08-31T04:51:51.068670+0100 - __main__ - ERROR - An error has been caught in function '<module>', process 'MainProcess' (479960), thread 'MainThread' (139772756756288):
Traceback (most recent call last):

> File "/home/mic/python/notes/apagar.py", line 37, in <module>
    apagar()
    └ <function apagar at 0x7f1f60841820>

  File "/home/mic/python/notes/apagar.py", line 27, in apagar
    filename = os.path.basename(record)
               │  │    │        └ ('http://localhost/notes/pages/html/uber.html',)
               │  │    └ <function basename at 0x7f1f613dba60>
               │  └ <module 'posixpath' from '/usr/lib/python3.9/posixpath.py'>
               └ <module 'os' from '/usr/lib/python3.9/os.py'>

  File "/usr/lib/python3.9/posixpath.py", line 142, in basename
    p = os.fspath(p)
        │  │      └ ('http://localhost/notes/pages/html/uber.html',)
        │  └ <built-in function fspath>
        └ <module 'os' from '/usr/lib/python3.9/os.py'>

TypeError: expected str, bytes or os.PathLike object, not tuple
2021-08-31T04:53:05.197478+0100 - __main__ - ERROR - An error has been caught in function '<module>', process 'MainProcess' (479991), thread 'MainThread' (140715504510784):
Traceback (most recent call last):

> File "/home/mic/python/notes/apagar.py", line 39, in <module>
    apagar()
    └ <function apagar at 0x7ffae0a93820>

  File "/home/mic/python/notes/apagar.py", line 29, in apagar
    filename = os.path.basename(record)
               │  │    │        └ ('http://localhost/notes/pages/html/uber.html',)
               │  │    └ <function basename at 0x7ffae162da60>
               │  └ <module 'posixpath' from '/usr/lib/python3.9/posixpath.py'>
               └ <module 'os' from '/usr/lib/python3.9/os.py'>

  File "/usr/lib/python3.9/posixpath.py", line 142, in basename
    p = os.fspath(p)
        │  │      └ ('http://localhost/notes/pages/html/uber.html',)
        │  └ <built-in function fspath>
        └ <module 'os' from '/usr/lib/python3.9/os.py'>

TypeError: expected str, bytes or os.PathLike object, not tuple
2021-08-31T05:00:14.847131+0100 - __main__ - ERROR - An error has been caught in function '<module>', process 'MainProcess' (480312), thread 'MainThread' (139667936692032):
Traceback (most recent call last):

> File "/home/mic/python/notes/apagar.py", line 42, in <module>
    apagar()
    └ <function apagar at 0x7f06f8c0e820>

  File "/home/mic/python/notes/apagar.py", line 32, in apagar
    cmd = "rm " + record + "; " + "rm " + md_page + "'"
                  │                       └ "/srv/http/notes/pages/markdown/contact.h.md'"
                  └ ('http://localhost/notes/pages/html/contact.html',)

TypeError: can only concatenate str (not "tuple") to str
2021-08-31T07:05:47.445002+0100 - __main__ - ERROR - An error has been caught in function '<module>', process 'MainProcess' (485128), thread 'MainThread' (140336416106304):
Traceback (most recent call last):

> File "/home/mic/python/notes/main.py", line 44, in <module>
    add_md_page()
    └ <function add_md_page at 0x7fa29cc22f70>

  File "/home/mic/python/notes/add.py", line 95, in add_md_page
    print(f"[*] - It was created the markdown file named, {add.md_path}.", fore="#acac87")

TypeError: 'fore' is an invalid keyword argument for print()
2021-09-05T00:47:05.966240+0100 - __main__ - ERROR - An error has been caught in function 'add', process 'MainProcess' (19287), thread 'MainThread' (139634917742400):
Traceback (most recent call last):

  File "/home/mic/python/notes/add.py", line 53, in <module>
    add()
    └ <function add at 0x7eff486313a0>

> File "/home/mic/python/notes/add.py", line 28, in add
    string_closeness()
    └ <function string_closeness at 0x7eff486310d0>

  File "/home/mic/python/notes/tag_management/string_closeness.py", line 17, in string_closeness
    for k in [kwd1, kwd2, kwd3]:

NameError: name 'kwd1' is not defined
2021-09-05T00:47:05.966240+0100 - __main__ - ERROR - An error has been caught in function 'add', process 'MainProcess' (19287), thread 'MainThread' (139634917742400):
Traceback (most recent call last):

  File "/home/mic/python/notes/add.py", line 53, in <module>
    add()
    └ <function add at 0x7eff486313a0>

> File "/home/mic/python/notes/add.py", line 28, in add
    string_closeness()
    └ <function string_closeness at 0x7eff486310d0>

  File "/home/mic/python/notes/tag_management/string_closeness.py", line 17, in string_closeness
    for k in [kwd1, kwd2, kwd3]:

NameError: name 'kwd1' is not defined
2021-09-05T00:47:51.901826+0100 - add - ERROR - An error has been caught in function 'add', process 'MainProcess' (19399), thread 'MainThread' (140475815765824):
Traceback (most recent call last):

  File "/home/mic/python/notes/main.py", line 43, in <module>
    add()
    └ <function add at 0x7fc3119b48b0>

> File "/home/mic/python/notes/add.py", line 28, in add
    string_closeness()
    └ <function string_closeness at 0x7fc3119b45e0>

  File "/home/mic/python/notes/tag_management/string_closeness.py", line 17, in string_closeness
    for k in [kwd1, kwd2, kwd3]:

NameError: name 'kwd1' is not defined
2021-09-05T00:47:51.901826+0100 - add - ERROR - An error has been caught in function 'add', process 'MainProcess' (19399), thread 'MainThread' (140475815765824):
Traceback (most recent call last):

  File "/home/mic/python/notes/main.py", line 43, in <module>
    add()
    └ <function add at 0x7fc3119b48b0>

> File "/home/mic/python/notes/add.py", line 28, in add
    string_closeness()
    └ <function string_closeness at 0x7fc3119b45e0>

  File "/home/mic/python/notes/tag_management/string_closeness.py", line 17, in string_closeness
    for k in [kwd1, kwd2, kwd3]:

NameError: name 'kwd1' is not defined
2021-09-05T00:47:51.901826+0100 - add - ERROR - An error has been caught in function 'add', process 'MainProcess' (19399), thread 'MainThread' (140475815765824):
Traceback (most recent call last):

  File "/home/mic/python/notes/main.py", line 43, in <module>
    add()
    └ <function add at 0x7fc3119b48b0>

> File "/home/mic/python/notes/add.py", line 28, in add
    string_closeness()
    └ <function string_closeness at 0x7fc3119b45e0>

  File "/home/mic/python/notes/tag_management/string_closeness.py", line 17, in string_closeness
    for k in [kwd1, kwd2, kwd3]:

NameError: name 'kwd1' is not defined
2021-09-05T00:52:58.184930+0100 - add - ERROR - An error has been caught in function 'add', process 'MainProcess' (19561), thread 'MainThread' (140384275449664):
Traceback (most recent call last):

  File "/home/mic/python/notes/main.py", line 43, in <module>
    add()
    └ <function add at 0x7fadc160f8b0>

> File "/home/mic/python/notes/add.py", line 28, in add
    string_closeness()
    └ <function string_closeness at 0x7fadc160f5e0>

TypeError: string_closeness() missing 3 required positional arguments: 'kwd1', 'kwd2', and 'kwd3'
2021-09-05T00:52:58.184930+0100 - add - ERROR - An error has been caught in function 'add', process 'MainProcess' (19561), thread 'MainThread' (140384275449664):
Traceback (most recent call last):

  File "/home/mic/python/notes/main.py", line 43, in <module>
    add()
    └ <function add at 0x7fadc160f8b0>

> File "/home/mic/python/notes/add.py", line 28, in add
    string_closeness()
    └ <function string_closeness at 0x7fadc160f5e0>

TypeError: string_closeness() missing 3 required positional arguments: 'kwd1', 'kwd2', and 'kwd3'
2021-09-05T00:52:58.184930+0100 - add - ERROR - An error has been caught in function 'add', process 'MainProcess' (19561), thread 'MainThread' (140384275449664):
Traceback (most recent call last):

  File "/home/mic/python/notes/main.py", line 43, in <module>
    add()
    └ <function add at 0x7fadc160f8b0>

> File "/home/mic/python/notes/add.py", line 28, in add
    string_closeness()
    └ <function string_closeness at 0x7fadc160f5e0>

TypeError: string_closeness() missing 3 required positional arguments: 'kwd1', 'kwd2', and 'kwd3'
2021-09-05T00:56:58.170950+0100 - add - ERROR - An error has been caught in function 'add', process 'MainProcess' (19909), thread 'MainThread' (140086795265856):
Traceback (most recent call last):

  File "/home/mic/python/notes/main.py", line 43, in <module>
    add()
    └ <function add at 0x7f687e2d98b0>

> File "/home/mic/python/notes/add.py", line 28, in add
    string_closeness()
    └ <function string_closeness at 0x7f687e2d95e0>

TypeError: string_closeness() missing 3 required positional arguments: 'kwd1', 'kwd2', and 'kwd3'
2021-09-05T00:56:58.170950+0100 - add - ERROR - An error has been caught in function 'add', process 'MainProcess' (19909), thread 'MainThread' (140086795265856):
Traceback (most recent call last):

  File "/home/mic/python/notes/main.py", line 43, in <module>
    add()
    └ <function add at 0x7f687e2d98b0>

> File "/home/mic/python/notes/add.py", line 28, in add
    string_closeness()
    └ <function string_closeness at 0x7f687e2d95e0>

TypeError: string_closeness() missing 3 required positional arguments: 'kwd1', 'kwd2', and 'kwd3'
2021-09-05T00:56:58.170950+0100 - add - ERROR - An error has been caught in function 'add', process 'MainProcess' (19909), thread 'MainThread' (140086795265856):
Traceback (most recent call last):

  File "/home/mic/python/notes/main.py", line 43, in <module>
    add()
    └ <function add at 0x7f687e2d98b0>

> File "/home/mic/python/notes/add.py", line 28, in add
    string_closeness()
    └ <function string_closeness at 0x7f687e2d95e0>

TypeError: string_closeness() missing 3 required positional arguments: 'kwd1', 'kwd2', and 'kwd3'
2021-09-05T01:23:23.900404+0100 - tag_management.new_msg - ERROR - An error has been caught in function '<module>', process 'MainProcess' (22362), thread 'MainThread' (140189105887040):
Traceback (most recent call last):

  File "/home/mic/python/notes/add.py", line 10, in <module>
    from tag_management.new_msg import string_closeness

  File "<frozen importlib._bootstrap>", line 1007, in _find_and_load
  File "<frozen importlib._bootstrap>", line 986, in _find_and_load_unlocked
  File "<frozen importlib._bootstrap>", line 680, in _load_unlocked
  File "<frozen importlib._bootstrap_external>", line 850, in exec_module
  File "<frozen importlib._bootstrap>", line 228, in _call_with_frames_removed

> File "/home/mic/python/notes/tag_management/new_msg.py", line 117, in <module>
    to.string_closeness()
    │  └ <function TagOutput.string_closeness at 0x7f805092ec10>
    └ <tag_management.new_msg.TagOutput object at 0x7f8050995ac0>

  File "/home/mic/python/notes/tag_management/new_msg.py", line 97, in string_closeness
    for i in get_tag_list.close:
             └ <function get_tag_list at 0x7f80509a5e50>

AttributeError: 'function' object has no attribute 'close'
2021-09-05T01:23:23.900404+0100 - tag_management.new_msg - ERROR - An error has been caught in function '<module>', process 'MainProcess' (22362), thread 'MainThread' (140189105887040):
Traceback (most recent call last):

  File "/home/mic/python/notes/add.py", line 10, in <module>
    from tag_management.new_msg import string_closeness

  File "<frozen importlib._bootstrap>", line 1007, in _find_and_load
  File "<frozen importlib._bootstrap>", line 986, in _find_and_load_unlocked
  File "<frozen importlib._bootstrap>", line 680, in _load_unlocked
  File "<frozen importlib._bootstrap_external>", line 850, in exec_module
  File "<frozen importlib._bootstrap>", line 228, in _call_with_frames_removed

> File "/home/mic/python/notes/tag_management/new_msg.py", line 117, in <module>
    to.string_closeness()
    │  └ <function TagOutput.string_closeness at 0x7f805092ec10>
    └ <tag_management.new_msg.TagOutput object at 0x7f8050995ac0>

  File "/home/mic/python/notes/tag_management/new_msg.py", line 97, in string_closeness
    for i in get_tag_list.close:
             └ <function get_tag_list at 0x7f80509a5e50>

AttributeError: 'function' object has no attribute 'close'
2021-09-05T01:28:02.168195+0100 - __main__ - ERROR - An error has been caught in function '<module>', process 'MainProcess' (22500), thread 'MainThread' (140618896762688):
Traceback (most recent call last):

> File "/home/mic/python/notes/add.py", line 50, in <module>
    add()
    └ <function add at 0x7fe4621f1550>

  File "/home/mic/python/notes/add.py", line 25, in add
    new_msg.string_closeness()
    └ <module 'tag_management.new_msg' from '/home/mic/python/notes/tag_management/new_msg.py'>

AttributeError: module 'tag_management.new_msg' has no attribute 'string_closeness'
2021-09-05T01:28:02.168195+0100 - __main__ - ERROR - An error has been caught in function '<module>', process 'MainProcess' (22500), thread 'MainThread' (140618896762688):
Traceback (most recent call last):

> File "/home/mic/python/notes/add.py", line 50, in <module>
    add()
    └ <function add at 0x7fe4621f1550>

  File "/home/mic/python/notes/add.py", line 25, in add
    new_msg.string_closeness()
    └ <module 'tag_management.new_msg' from '/home/mic/python/notes/tag_management/new_msg.py'>

AttributeError: module 'tag_management.new_msg' has no attribute 'string_closeness'
2021-09-05T01:28:02.180698+0100 - __main__ - ERROR - An error has been caught in function '<module>', process 'MainProcess' (22500), thread 'MainThread' (140618896762688):
Traceback (most recent call last):

> File "/home/mic/python/notes/add.py", line 108, in <module>
    add_md_page()
    └ <function add_md_page at 0x7fe4621bc1f0>

  File "/home/mic/python/notes/add.py", line 88, in add_md_page
    with open(add.md_path, "w") as f:
              └ <function add at 0x7fe4621f1550>

AttributeError: 'function' object has no attribute 'md_path'
2021-09-05T01:28:02.180698+0100 - __main__ - ERROR - An error has been caught in function '<module>', process 'MainProcess' (22500), thread 'MainThread' (140618896762688):
Traceback (most recent call last):

> File "/home/mic/python/notes/add.py", line 108, in <module>
    add_md_page()
    └ <function add_md_page at 0x7fe4621bc1f0>

  File "/home/mic/python/notes/add.py", line 88, in add_md_page
    with open(add.md_path, "w") as f:
              └ <function add at 0x7fe4621f1550>

AttributeError: 'function' object has no attribute 'md_path'
2021-09-05T01:28:02.182584+0100 - __main__ - ERROR - An error has been caught in function '<module>', process 'MainProcess' (22500), thread 'MainThread' (140618896762688):
Traceback (most recent call last):

> File "/home/mic/python/notes/add.py", line 136, in <module>
    add_html_page()
    └ <function add_html_page at 0x7fe46216f8b0>

  File "/home/mic/python/notes/add.py", line 117, in add_html_page
    html_path = "/srv/http/notes/pages/html/" + add.tit + ".html"
                                                └ <function add at 0x7fe4621f1550>

AttributeError: 'function' object has no attribute 'tit'
2021-09-05T01:28:02.182584+0100 - __main__ - ERROR - An error has been caught in function '<module>', process 'MainProcess' (22500), thread 'MainThread' (140618896762688):
Traceback (most recent call last):

> File "/home/mic/python/notes/add.py", line 136, in <module>
    add_html_page()
    └ <function add_html_page at 0x7fe46216f8b0>

  File "/home/mic/python/notes/add.py", line 117, in add_html_page
    html_path = "/srv/http/notes/pages/html/" + add.tit + ".html"
                                                └ <function add at 0x7fe4621f1550>

AttributeError: 'function' object has no attribute 'tit'
2021-09-05T01:32:44.656246+0100 - __main__ - ERROR - An error has been caught in function 'add', process 'MainProcess' (22661), thread 'MainThread' (140534661678912):
Traceback (most recent call last):

  File "/home/mic/python/notes/add.py", line 50, in <module>
    add()
    └ <function add at 0x7fd0c551b790>

> File "/home/mic/python/notes/add.py", line 25, in add
    TagOutput.string_closeness()
    │         └ <function TagOutput.string_closeness at 0x7fd0c54ddc10>
    └ <class 'tag_management.new_msg.TagOutput'>

TypeError: string_closeness() missing 1 required positional argument: 'self'
2021-09-05T01:32:44.656246+0100 - __main__ - ERROR - An error has been caught in function 'add', process 'MainProcess' (22661), thread 'MainThread' (140534661678912):
Traceback (most recent call last):

  File "/home/mic/python/notes/add.py", line 50, in <module>
    add()
    └ <function add at 0x7fd0c551b790>

> File "/home/mic/python/notes/add.py", line 25, in add
    TagOutput.string_closeness()
    │         └ <function TagOutput.string_closeness at 0x7fd0c54ddc10>
    └ <class 'tag_management.new_msg.TagOutput'>

TypeError: string_closeness() missing 1 required positional argument: 'self'
2021-09-21T23:32:55.590820+0100 - __main__ - ERROR - An error has been caught in function '<module>', process 'MainProcess' (72401), thread 'MainThread' (140398374573888):
Traceback (most recent call last):

> File "/home/mic/python/notes/main.py", line 54, in <module>
    del_md_html_pages()
    └ <function del_md_html_pages at 0x7fb109beae50>

  File "/home/mic/python/notes/delete.py", line 25, in del_md_html_pages
    path = record[0]
           └ None

TypeError: 'NoneType' object is not subscriptable
2021-09-29T12:22:38.440844+0100 - __main__ - ERROR - An error has been caught in function '<module>', process 'MainProcess' (88663), thread 'MainThread' (140019971577664):
Traceback (most recent call last):

> File "/home/mic/python/notes/stats.py", line 42, in <module>
    tag_list()
    └ <function tag_list at 0x7f58efaab940>

TypeError: tag_list() missing 1 required positional argument: 'self'
2021-09-29T12:58:01.380509+0100 - __main__ - ERROR - An error has been caught in function '<module>', process 'MainProcess' (91815), thread 'MainThread' (140313186301760):
Traceback (most recent call last):

> File "/home/mic/python/notes/stats.py", line 46, in <module>
    tag_list()
    └ <function tag_list at 0x7f9d346bbc10>

  File "/home/mic/python/notes/stats.py", line 36, in tag_list
    print(color(i[0], fore="#acac87"))
          │     └ 1
          └ <bound method Colr.color of ''>

TypeError: 'int' object is not subscriptable
2021-09-29T12:58:42.165009+0100 - __main__ - ERROR - An error has been caught in function '<module>', process 'MainProcess' (91841), thread 'MainThread' (140377099978560):
Traceback (most recent call last):

> File "/home/mic/python/notes/stats.py", line 46, in <module>
    tag_list()
    └ <function tag_list at 0x7fac15f91ca0>

  File "/home/mic/python/notes/stats.py", line 36, in tag_list
    print(color(str(i[0]), fore="#acac87"))
          │         └ 1
          └ <bound method Colr.color of ''>

TypeError: 'int' object is not subscriptable
2021-09-29T12:59:53.365981+0100 - __main__ - ERROR - An error has been caught in function '<module>', process 'MainProcess' (91888), thread 'MainThread' (140596254820160):
Traceback (most recent call last):

> File "/home/mic/python/notes/stats.py", line 46, in <module>
    tag_list()
    └ <function tag_list at 0x7fdf1c9e8c10>

  File "/home/mic/python/notes/stats.py", line 36, in tag_list
    print(color(t[0], fore="#acac87"))
          │     └ 1
          └ <bound method Colr.color of ''>

TypeError: 'int' object is not subscriptable
2021-09-29T13:00:40.514474+0100 - __main__ - ERROR - An error has been caught in function '<module>', process 'MainProcess' (91917), thread 'MainThread' (140286631565120):
Traceback (most recent call last):

> File "/home/mic/python/notes/stats.py", line 46, in <module>
    tag_list()
    └ <function tag_list at 0x7f9705a29c10>

  File "/home/mic/python/notes/stats.py", line 36, in tag_list
    print(color(t[0], fore="#acac87"))
          │     └ 1
          └ <bound method Colr.color of ''>

TypeError: 'int' object is not subscriptable
2021-09-29T13:01:47.252057+0100 - __main__ - ERROR - An error has been caught in function '<module>', process 'MainProcess' (91958), thread 'MainThread' (140337175824192):
Traceback (most recent call last):

> File "/home/mic/python/notes/stats.py", line 46, in <module>
    tag_list()
    └ <function tag_list at 0x7fa2ca4edca0>

  File "/home/mic/python/notes/stats.py", line 37, in tag_list
    print(color(t[1], fore="#f18892"))
          │     └ 1
          └ <bound method Colr.color of ''>

TypeError: 'int' object is not subscriptable
2021-09-29T13:02:13.290528+0100 - __main__ - ERROR - An error has been caught in function '<module>', process 'MainProcess' (91970), thread 'MainThread' (140529573816128):
Traceback (most recent call last):

> File "/home/mic/python/notes/stats.py", line 46, in <module>
    tag_list()
    └ <function tag_list at 0x7fcf961f3ca0>

  File "/home/mic/python/notes/stats.py", line 37, in tag_list
    print(color(str(t)[1], fore="#f18892"))
          │         └ 1
          └ <bound method Colr.color of ''>

IndexError: string index out of range
2021-09-29T13:05:15.581240+0100 - __main__ - ERROR - An error has been caught in function '<module>', process 'MainProcess' (92077), thread 'MainThread' (139643179718464):
Traceback (most recent call last):

> File "/home/mic/python/notes/stats.py", line 46, in <module>
    tag_list()
    └ <function tag_list at 0x7f0134ea9c10>

  File "/home/mic/python/notes/stats.py", line 36, in tag_list
    print(color(t[0], fore="#acac87"))
          │     └ 1
          └ <bound method Colr.color of ''>

TypeError: 'int' object is not subscriptable
2021-09-29T13:17:42.326019+0100 - __main__ - ERROR - An error has been caught in function '<module>', process 'MainProcess' (92718), thread 'MainThread' (139943849625408):
Traceback (most recent call last):

> File "/home/mic/python/notes/stats.py", line 46, in <module>
    tag_list()
    └ <function tag_list at 0x7f47363d5ca0>

  File "/home/mic/python/notes/stats.py", line 37, in tag_list
    print(color("  ", x, fore="#acac87")), print(color("  ", y, fore="#f18892"))
          │           │                          │           └ 1
          │           │                          └ <bound method Colr.color of ''>
          │           └ '80'
          └ <bound method Colr.color of ''>

TypeError: color() got multiple values for argument 'fore'
2021-09-29T13:20:24.978943+0100 - __main__ - ERROR - An error has been caught in function '<module>', process 'MainProcess' (92807), thread 'MainThread' (140482890983232):
Traceback (most recent call last):

> File "/home/mic/python/notes/stats.py", line 46, in <module>
    tag_list()
    └ <function tag_list at 0x7fc4b79bbca0>

  File "/home/mic/python/notes/stats.py", line 37, in tag_list
    print(color("  " + x, fore="#acac87")), print(color("  " + y, fore="#f18892"))
          │            │                          │            └ 1
          │            │                          └ <bound method Colr.color of ''>
          │            └ '80'
          └ <bound method Colr.color of ''>

TypeError: can only concatenate str (not "int") to str
2021-09-29T14:07:49.358905+0100 - __main__ - ERROR - An error has been caught in function '<module>', process 'MainProcess' (95301), thread 'MainThread' (139629061678912):
Traceback (most recent call last):

> File "/home/mic/python/notes/stats.py", line 70, in <module>
    entries()
    └ <function entries at 0x7efdeb6b2f70>

  File "/home/mic/python/notes/stats.py", line 61, in entries
    print(color("The number of database entries is ", records, fore="#f2b26d"))
          │                                           └ [214]
          └ <bound method Colr.color of ''>

TypeError: color() got multiple values for argument 'fore'
2021-09-29T14:23:26.492924+0100 - __main__ - ERROR - An error has been caught in function '<module>', process 'MainProcess' (95811), thread 'MainThread' (140598063843136):
Traceback (most recent call last):

> File "/home/mic/python/notes/stats.py", line 74, in <module>
    entries()
    └ <function entries at 0x7fdf8872df70>

  File "/home/mic/python/notes/stats.py", line 61, in entries
    tag_num = int(records) * 3
                  └ [214]

TypeError: int() argument must be a string, a bytes-like object or a number, not 'list'
2021-09-29T14:45:26.107348+0100 - __main__ - ERROR - An error has been caught in function '<module>', process 'MainProcess' (97096), thread 'MainThread' (140131432712000):
Traceback (most recent call last):

> File "/home/mic/python/notes/stats.py", line 106, in <module>
    tags()
    └ <function tags at 0x7f72e30ba430>

  File "/home/mic/python/notes/stats.py", line 97, in tags
    print(sum(records))
              └ '133'

TypeError: unsupported operand type(s) for +: 'int' and 'str'
2021-09-29T14:46:16.826513+0100 - __main__ - ERROR - An error has been caught in function '<module>', process 'MainProcess' (97123), thread 'MainThread' (139696795912000):
Traceback (most recent call last):

> File "/home/mic/python/notes/stats.py", line 106, in <module>
    tags()
    └ <function tags at 0x7f0db0ac6430>

  File "/home/mic/python/notes/stats.py", line 97, in tags
    print(sum(int(records)))
                  └ '133'

TypeError: 'int' object is not iterable
2021-09-29T14:48:52.194205+0100 - __main__ - ERROR - An error has been caught in function '<module>', process 'MainProcess' (97305), thread 'MainThread' (140296012764992):
Traceback (most recent call last):

> File "/home/mic/python/notes/stats.py", line 107, in <module>
    tags()
    └ <function tags at 0x7f9934c7f430>

  File "/home/mic/python/notes/stats.py", line 98, in tags
    print(sum(records))
              └ 133

TypeError: 'int' object is not iterable
2021-09-29T14:51:33.582412+0100 - __main__ - ERROR - An error has been caught in function '<module>', process 'MainProcess' (97386), thread 'MainThread' (140229691053888):
Traceback (most recent call last):

> File "/home/mic/python/notes/stats.py", line 108, in <module>
    tags()
    └ <function tags at 0x7f89c3b2f430>

  File "/home/mic/python/notes/stats.py", line 98, in tags
    for i in records:
             └ 133

TypeError: 'int' object is not iterable
2021-09-29T14:51:47.991779+0100 - __main__ - ERROR - An error has been caught in function '<module>', process 'MainProcess' (97396), thread 'MainThread' (140552320956224):
Traceback (most recent call last):

> File "/home/mic/python/notes/stats.py", line 108, in <module>
    tags()
    └ <function tags at 0x7fd4e1f09430>

  File "/home/mic/python/notes/stats.py", line 98, in tags
    for i in records:
             └ 133

TypeError: 'int' object is not iterable
2021-09-29T14:54:28.611852+0100 - __main__ - ERROR - An error has been caught in function '<module>', process 'MainProcess' (97612), thread 'MainThread' (139955198383936):
Traceback (most recent call last):

> File "/home/mic/python/notes/stats.py", line 107, in <module>
    tags()
    └ <function tags at 0x7f49daa93430>

  File "/home/mic/python/notes/stats.py", line 98, in tags
    print(sum(records))
              └ ['133']

TypeError: unsupported operand type(s) for +: 'int' and 'str'
2021-09-29T14:58:21.063248+0100 - __main__ - ERROR - An error has been caught in function '<module>', process 'MainProcess' (97848), thread 'MainThread' (140285365278528):
Traceback (most recent call last):

> File "/home/mic/python/notes/stats.py", line 107, in <module>
    tags()
    └ <function tags at 0x7f96ba243430>

  File "/home/mic/python/notes/stats.py", line 98, in tags
    print(records[1])
          └ ['133']

IndexError: list index out of range
2021-09-29T15:24:59.632527+0100 - __main__ - ERROR - An error has been caught in function '<module>', process 'MainProcess' (99066), thread 'MainThread' (140434447628096):
Traceback (most recent call last):

> File "/home/mic/python/notes/stats.py", line 100, in <module>
    tags()
    └ <function tags at 0x7fb9702453a0>

  File "/home/mic/python/notes/stats.py", line 87, in tags
    cur.execute(
    │   └ <function MySQLCursor.execute at 0x7fb970277820>
    └ <mysql.connector.cursor.MySQLCursor object at 0x7fb97028e850>

  File "/usr/lib/python3.9/site-packages/mysql/connector/cursor.py", line 528, in execute
    stmt = operation.encode(self._connection.python_charset)
           │                │    └ <weakproxy at 0x7fb970225f90 to MySQLConnection at 0x7fb97028eac0>
           │                └ <mysql.connector.cursor.MySQLCursor object at 0x7fb97028e850>
           └ ('SELECT COUNT(DISTINCT k1) FROM notes',)

AttributeError: 'tuple' object has no attribute 'encode'
2021-09-29T15:25:46.023819+0100 - __main__ - ERROR - An error has been caught in function '<module>', process 'MainProcess' (99092), thread 'MainThread' (140054228809536):
Traceback (most recent call last):

> File "/home/mic/python/notes/stats.py", line 100, in <module>
    tags()
    └ <function tags at 0x7f60e95593a0>

  File "/home/mic/python/notes/stats.py", line 87, in tags
    cur.execute(
    │   └ <function MySQLCursor.execute at 0x7f60e958b820>
    └ <mysql.connector.cursor.MySQLCursor object at 0x7f60e95a2850>

  File "/usr/lib/python3.9/site-packages/mysql/connector/cursor.py", line 528, in execute
    stmt = operation.encode(self._connection.python_charset)
           │                │    └ <weakproxy at 0x7f60e9552220 to MySQLConnection at 0x7f60e95a2ac0>
           │                └ <mysql.connector.cursor.MySQLCursor object at 0x7f60e95a2850>
           └ ('SELECT COUNT(DISTINCT k1) FROM notes',)

AttributeError: 'tuple' object has no attribute 'encode'
2021-09-29T15:33:15.740848+0100 - __main__ - ERROR - An error has been caught in function '<module>', process 'MainProcess' (99613), thread 'MainThread' (140191019562816):
Traceback (most recent call last):

> File "/home/mic/python/notes/stats.py", line 118, in <module>
    tags()
    └ <function tags at 0x7f80c2b2d3a0>

  File "/home/mic/python/notes/stats.py", line 107, in tags
    soma = tuple(map(sum(recordk1, recordk2, recordk3)))
                         │         │         └ (153,)
                         │         └ (147,)
                         └ (133,)

TypeError: sum() takes at most 2 arguments (3 given)
