2021-08-22T08:22:16.831217+0100 - __main__ - ERROR - An error has been caught in function '<module>', process 'MainProcess' (82917), thread 'MainThread' (140318201493312):
Traceback (most recent call last):

> File "/home/mic/python/encrypt_diary/teste.py", line 30, in <module>
    function()
    └ <function function at 0x7f9e5fa11670>

  File "/home/mic/python/encrypt_diary/teste.py", line 27, in function
    db.execute("select * from people;").fetchall()
    │  └ <method 'execute' of 'pysqlcipher3.dbapi2.Connection' objects>
    └ <pysqlcipher3.dbapi2.Connection object at 0x7f9e5fa252d0>

pysqlcipher3.dbapi2.OperationalError: no such table: people
2021-08-22T09:22:23.949429+0100 - add - INFO - ['Pyment', 'docstrings', 'documentation', 'pyment', '\n To configure and prettify your docstrings,\n use the following command:\n ------------------------------------------\n pyment -w <file_name>\n ------------------------------------------\n https://github.com/dadadel/pyment']
2021-08-22T09:22:23.953822+0100 - add - INFO - INSERT INTO notes (title, k1, k2, k3, note)
                VALUES (%s, %s, %s, %s, %s)
2021-08-22T10:26:18.245013+0100 - __main__ - ERROR - An error has been caught in function '<module>', process 'MainProcess' (89920), thread 'MainThread' (140422830589760):
Traceback (most recent call last):

> File "/home/mic/python/encrypt_diary/diary.py", line 114, in <module>
    initialize(passphrase)
    │          └ 'passphrase'
    └ <function initialize at 0x7fb6bb86d8b0>

  File "/home/mic/python/encrypt_diary/diary.py", line 46, in initialize
    Entry.create_table()
    │     └ <classmethod object at 0x7fb6bb8546a0>
    └ <Model: Entry>

  File "/home/mic/.local/lib/python3.9/site-packages/peewee.py", line 6672, in create_table
    cls._schema.create_all(safe, **options)
    │   │       │          │       └ {}
    │   │       │          └ True
    │   │       └ <function SchemaManager.create_all at 0x7fb6bb850430>
    │   └ <peewee.SchemaManager object at 0x7fb6bb86ba00>
    └ <Model: Entry>
  File "/home/mic/.local/lib/python3.9/site-packages/peewee.py", line 5783, in create_all
    self.create_table(safe, **table_options)
    │    │            │       └ {}
    │    │            └ True
    │    └ <function SchemaManager.create_table at 0x7fb6bb84e790>
    └ <peewee.SchemaManager object at 0x7fb6bb86ba00>
  File "/home/mic/.local/lib/python3.9/site-packages/peewee.py", line 5638, in create_table
    self.database.execute(self._create_table(safe=safe, **options))
    │    │                │    │                  │       └ {}
    │    │                │    │                  └ True
    │    │                │    └ <function SchemaManager._create_table at 0x7fb6bb84e670>
    │    │                └ <peewee.SchemaManager object at 0x7fb6bb86ba00>
    │    └ <property object at 0x7fb6bb847c70>
    └ <peewee.SchemaManager object at 0x7fb6bb86ba00>
  File "/home/mic/.local/lib/python3.9/site-packages/peewee.py", line 3157, in execute
    return self.execute_sql(sql, params, commit=commit)
           │    │           │    │              └ <object object at 0x7fb6bbf7e360>
           │    │           │    └ []
           │    │           └ 'CREATE TABLE IF NOT EXISTS "entry" ("id" INTEGER NOT NULL PRIMARY KEY, "content" TEXT NOT NULL, "timestamp" DATETIME NOT NULL)'
           │    └ <function Database.execute_sql at 0x7fb6bb8af430>
           └ <playhouse.sqlcipher_ext.SqlCipherDatabase object at 0x7fb6bb86b8b0>
  File "/home/mic/.local/lib/python3.9/site-packages/peewee.py", line 3142, in execute_sql
    cursor = self.cursor(commit)
             │    │      └ True
             │    └ <function Database.cursor at 0x7fb6bb8af3a0>
             └ <playhouse.sqlcipher_ext.SqlCipherDatabase object at 0x7fb6bb86b8b0>
  File "/home/mic/.local/lib/python3.9/site-packages/peewee.py", line 3126, in cursor
    self.connect()
    │    └ <function Database.connect at 0x7fb6bb8abee0>
    └ <playhouse.sqlcipher_ext.SqlCipherDatabase object at 0x7fb6bb86b8b0>
  File "/home/mic/.local/lib/python3.9/site-packages/peewee.py", line 3080, in connect
    self._state.set_connection(self._connect())
    │    │      │              │    └ <function _SqlCipherDatabase._connect at 0x7fb6bb86d5e0>
    │    │      │              └ <playhouse.sqlcipher_ext.SqlCipherDatabase object at 0x7fb6bb86b8b0>
    │    │      └ <function _ConnectionState.set_connection at 0x7fb6bb8ab820>
    │    └ <peewee._ConnectionLocal object at 0x7fb6bb84d940>
    └ <playhouse.sqlcipher_ext.SqlCipherDatabase object at 0x7fb6bb86b8b0>
  File "/home/mic/.local/lib/python3.9/site-packages/playhouse/sqlcipher_ext.py", line 71, in _connect
    conn = sqlcipher.connect(self.database, isolation_level=None, **params)
           │         │       │    │                                 └ {'kdf_iter': 64000}
           │         │       │    └ 'micro_blog.db'
           │         │       └ <playhouse.sqlcipher_ext.SqlCipherDatabase object at 0x7fb6bb86b8b0>
           │         └ <built-in function connect>
           └ <module 'pysqlcipher3.dbapi2' from '/home/mic/.local/lib/python3.9/site-packages/pysqlcipher3/dbapi2.py'>

TypeError: 'kdf_iter' is an invalid keyword argument for this function
2021-08-22T10:26:18.254378+0100 - __main__ - ERROR - An error has been caught in function '<module>', process 'MainProcess' (89920), thread 'MainThread' (140422830589760):
Traceback (most recent call last):

> File "/home/mic/python/encrypt_diary/diary.py", line 115, in <module>
    menu_loop()
    └ <function menu_loop at 0x7fb6bb86dc10>

  File "/home/mic/python/encrypt_diary/diary.py", line 55, in menu_loop
    choice = raw_input("Actions: ").lower().strip()

NameError: name 'raw_input' is not defined
2021-08-22T10:27:41.519030+0100 - __main__ - ERROR - An error has been caught in function '<module>', process 'MainProcess' (89976), thread 'MainThread' (139712121169728):
Traceback (most recent call last):

> File "/home/mic/python/encrypt_diary/diary.py", line 115, in <module>
    menu_loop()
    └ <function menu_loop at 0x7f1141f1bc10>

  File "/home/mic/python/encrypt_diary/diary.py", line 55, in menu_loop
    choice = raw_input("Actions: ").lower().strip()

NameError: name 'raw_input' is not defined
2021-08-22T10:28:14.328905+0100 - __main__ - ERROR - An error has been caught in function '<module>', process 'MainProcess' (89987), thread 'MainThread' (140572568958784):
Traceback (most recent call last):

> File "/home/mic/python/encrypt_diary/diary.py", line 115, in <module>
    menu_loop()
    └ <function menu_loop at 0x7fd998a10c10>

  File "/home/mic/python/encrypt_diary/diary.py", line 55, in menu_loop
    choice = raw_input("Actions: ").lower().strip()

NameError: name 'raw_input' is not defined
2021-08-22T10:29:26.994085+0100 - __main__ - ERROR - An error has been caught in function '<module>', process 'MainProcess' (90037), thread 'MainThread' (139765186049856):
Traceback (most recent call last):

> File "/home/mic/python/encrypt_diary/diary.py", line 115, in <module>
    menu_loop()
    └ <function menu_loop at 0x7f1d9cdb8c10>

  File "/home/mic/python/encrypt_diary/diary.py", line 55, in menu_loop
    choice = raw_input("Actions: ").lower().strip()

NameError: name 'raw_input' is not defined
2021-08-22T11:03:38.897895+0100 - __main__ - ERROR - An error has been caught in function '<module>', process 'MainProcess' (90995), thread 'MainThread' (140397731313472):
Traceback (most recent call last):

> File "/home/mic/python/encrypt_diary/diary.py", line 116, in <module>
    menu_loop()
    └ <function menu_loop at 0x7fb0e3315ca0>

  File "/home/mic/python/encrypt_diary/diary.py", line 56, in menu_loop
    choice = input(color("Actions: ", fore="#c3bcb1")).lower().strip()
                   └ <bound method Colr.color of ''>

EOFError
2021-08-22T14:12:15.958088+0100 - __main__ - ERROR - An error has been caught in function '<module>', process 'MainProcess' (99194), thread 'MainThread' (140712216049472):
Traceback (most recent call last):

> File "/home/mic/python/encrypt_diary/diary.py", line 126, in <module>
    initialize(passphrase)
    │          └ 'passphrase'
    └ <function initialize at 0x7ffa1bf1b4c0>

  File "/home/mic/python/encrypt_diary/diary.py", line 47, in initialize
    db.init("micro_blog.db", passphrase=os.environ("MICRO_PWD"))
    │  │                                │  └ environ({'SHELL': '/usr/bin/zsh', 'LSCOLORS': 'Gxfxcxdxbxegedabagacad', 'MARKER_DATA_HOME': '/home/mic/.local/share/marker', ...
    │  │                                └ <module 'os' from '/usr/lib/python3.9/os.py'>
    │  └ <function SqliteDatabase.init at 0x7ffa1c3acee0>
    └ <playhouse.sqlcipher_ext.SqlCipherDatabase object at 0x7ffa1bf15460>

TypeError: '_Environ' object is not callable
2021-08-22T14:14:15.336156+0100 - __main__ - ERROR - An error has been caught in function '<module>', process 'MainProcess' (99272), thread 'MainThread' (139965634414400):
Traceback (most recent call last):

> File "/home/mic/python/encrypt_diary/diary.py", line 127, in <module>
    initialize(passphrase)
    │          └ 'passphrase'
    └ <function initialize at 0x7f4c483604c0>

  File "/home/mic/python/encrypt_diary/diary.py", line 47, in initialize
    pwd = str(os.environ("MICRO_PWD"))
              │  └ environ({'SHELL': '/usr/bin/zsh', 'LSCOLORS': 'Gxfxcxdxbxegedabagacad', 'MARKER_DATA_HOME': '/home/mic/.local/share/marker', ...
              └ <module 'os' from '/usr/lib/python3.9/os.py'>

TypeError: '_Environ' object is not callable
2021-08-22T14:17:23.444287+0100 - __main__ - ERROR - An error has been caught in function '<module>', process 'MainProcess' (99497), thread 'MainThread' (139681062569792):
Traceback (most recent call last):

> File "/home/mic/python/encrypt_diary/diary.py", line 127, in <module>
    initialize(passphrase)
    │          └ 'passphrase'
    └ <function initialize at 0x7f0a066844c0>

  File "/home/mic/python/encrypt_diary/diary.py", line 47, in initialize
    pwd = str(os.environ["MICRO_PWD"])
              │  └ environ({'SHELL': '/usr/bin/zsh', 'LSCOLORS': 'Gxfxcxdxbxegedabagacad', 'MARKER_DATA_HOME': '/home/mic/.local/share/marker', ...
              └ <module 'os' from '/usr/lib/python3.9/os.py'>

  File "/usr/lib/python3.9/os.py", line 679, in __getitem__
    raise KeyError(key) from None
                   └ 'MICRO_PWD'

KeyError: 'MICRO_PWD'
2021-08-22T14:19:57.842319+0100 - __main__ - ERROR - An error has been caught in function '<module>', process 'MainProcess' (99588), thread 'MainThread' (140123275712320):
Traceback (most recent call last):

> File "/home/mic/python/encrypt_diary/diary.py", line 127, in <module>
    initialize(passphrase)
    │          └ 'passphrase'
    └ <function initialize at 0x7f70fc5d54c0>

  File "/home/mic/python/encrypt_diary/diary.py", line 47, in initialize
    pwd = str(os.environ["MICRO_PWD"])
              │  └ environ({'SHELL': '/usr/bin/zsh', 'LSCOLORS': 'Gxfxcxdxbxegedabagacad', 'MARKER_DATA_HOME': '/home/mic/.local/share/marker', ...
              └ <module 'os' from '/usr/lib/python3.9/os.py'>

  File "/usr/lib/python3.9/os.py", line 679, in __getitem__
    raise KeyError(key) from None
                   └ 'MICRO_PWD'

KeyError: 'MICRO_PWD'
2021-08-22T15:01:14.563217+0100 - __main__ - ERROR - An error has been caught in function '<module>', process 'MainProcess' (101795), thread 'MainThread' (139658537736000):
Traceback (most recent call last):

> File "/home/mic/python/encrypt_diary/diary.py", line 127, in <module>
    initialize(passphrase)
    │          └ 'passphrase'
    └ <function initialize at 0x7f04c7d294c0>

  File "/home/mic/python/encrypt_diary/diary.py", line 49, in initialize
    Entry.create_table()
    │     └ <classmethod object at 0x7f04c81e1430>
    └ <Model: Entry>

  File "/home/mic/.local/lib/python3.9/site-packages/peewee.py", line 6672, in create_table
    cls._schema.create_all(safe, **options)
    │   │       │          │       └ {}
    │   │       │          └ True
    │   │       └ <function SchemaManager.create_all at 0x7f04c81dc550>
    │   └ <peewee.SchemaManager object at 0x7f04c7d23580>
    └ <Model: Entry>
  File "/home/mic/.local/lib/python3.9/site-packages/peewee.py", line 5783, in create_all
    self.create_table(safe, **table_options)
    │    │            │       └ {}
    │    │            └ True
    │    └ <function SchemaManager.create_table at 0x7f04c81d98b0>
    └ <peewee.SchemaManager object at 0x7f04c7d23580>
  File "/home/mic/.local/lib/python3.9/site-packages/peewee.py", line 5638, in create_table
    self.database.execute(self._create_table(safe=safe, **options))
    │    │                │    │                  │       └ {}
    │    │                │    │                  └ True
    │    │                │    └ <function SchemaManager._create_table at 0x7f04c81d9790>
    │    │                └ <peewee.SchemaManager object at 0x7f04c7d23580>
    │    └ <property object at 0x7f04c81d2c20>
    └ <peewee.SchemaManager object at 0x7f04c7d23580>
  File "/home/mic/.local/lib/python3.9/site-packages/peewee.py", line 3157, in execute
    return self.execute_sql(sql, params, commit=commit)
           │    │           │    │              └ <object object at 0x7f04c8909360>
           │    │           │    └ []
           │    │           └ 'CREATE TABLE IF NOT EXISTS "entry" ("id" INTEGER NOT NULL PRIMARY KEY, "content" TEXT NOT NULL, "timestamp" DATETIME NOT NULL)'
           │    └ <function Database.execute_sql at 0x7f04c81b9550>
           └ <playhouse.sqlcipher_ext.SqlCipherDatabase object at 0x7f04c7d23430>
  File "/home/mic/.local/lib/python3.9/site-packages/peewee.py", line 3142, in execute_sql
    cursor = self.cursor(commit)
             │    │      └ True
             │    └ <function Database.cursor at 0x7f04c81b94c0>
             └ <playhouse.sqlcipher_ext.SqlCipherDatabase object at 0x7f04c7d23430>
  File "/home/mic/.local/lib/python3.9/site-packages/peewee.py", line 3126, in cursor
    self.connect()
    │    └ <function Database.connect at 0x7f04c81b9040>
    └ <playhouse.sqlcipher_ext.SqlCipherDatabase object at 0x7f04c7d23430>
  File "/home/mic/.local/lib/python3.9/site-packages/peewee.py", line 3080, in connect
    self._state.set_connection(self._connect())
    │    │      │              │    └ <function _SqlCipherDatabase._connect at 0x7f04c81f7700>
    │    │      │              └ <playhouse.sqlcipher_ext.SqlCipherDatabase object at 0x7f04c7d23430>
    │    │      └ <function _ConnectionState.set_connection at 0x7f04c8238940>
    │    └ <peewee._ConnectionLocal object at 0x7f04c7d1f760>
    └ <playhouse.sqlcipher_ext.SqlCipherDatabase object at 0x7f04c7d23430>
  File "/home/mic/.local/lib/python3.9/site-packages/playhouse/sqlcipher_ext.py", line 75, in _connect
    self._add_conn_hooks(conn)
    │    │               └ <pysqlcipher3.dbapi2.Connection object at 0x7f04c7f7e730>
    │    └ <function SqliteDatabase._add_conn_hooks at 0x7f04c81bb0d0>
    └ <playhouse.sqlcipher_ext.SqlCipherDatabase object at 0x7f04c7d23430>
  File "/home/mic/.local/lib/python3.9/site-packages/peewee.py", line 3429, in _add_conn_hooks
    self._set_pragmas(conn)
    │    │            └ <pysqlcipher3.dbapi2.Connection object at 0x7f04c7f7e730>
    │    └ <function SqliteDatabase._set_pragmas at 0x7f04c81bb160>
    └ <playhouse.sqlcipher_ext.SqlCipherDatabase object at 0x7f04c7d23430>
  File "/home/mic/.local/lib/python3.9/site-packages/peewee.py", line 3443, in _set_pragmas
    for pragma, value in self._pragmas:
                         │    └ 'passphrase'
                         └ <playhouse.sqlcipher_ext.SqlCipherDatabase object at 0x7f04c7d23430>

ValueError: not enough values to unpack (expected 2, got 1)
2021-10-22T13:39:48.745155+0100 - __main__ - ERROR - An error has been caught in function '<module>', process 'MainProcess' (211738), thread 'MainThread' (140630894528320):
Traceback (most recent call last):

> File "/home/mic/python/encrypt_diary/diary.py", line 133, in <module>
    menu_loop()
    └ <function menu_loop at 0x7fe72cadbdc0>

  File "/home/mic/python/encrypt_diary/diary.py", line 51, in menu_loop
    choice = input(color("Actions: ", fore="#c3bcb1")).lower().strip()
                   └ <bound method Colr.color of ''>

EOFError
